Workbook

Sheet spesa
A1: --
C3: filtro
C6: no
C11: no
C13: no
C14: no
C15: no
C16: no
C17: no
C19: 320
C20: no
C21: no
C22: no
C23: no
C27: no
C28: no
C29: no
C31: no
C32: no
C33: no
C34: no
C35: no
... C43: no
C44: 200
C45: no
C46: no
C47: no
C49: no
C50: no
C51: no
C53: no
C55: no
C56: no
C57: no
C61: no
C63: no
... C67: no

Sheet banca dati
A1: Colazione | C1: yogurt scremato | E1: frutta | G1: verdura | I1: carne e hamburger | K1: pesce | M1: latticini e salumi | O1: carboidrati
A2: biscotti magretti | C2: bresaola | G2: bieta
A3: biscotti misura privolat | C3: cioccolato fondente | G3: bietole
A4: burro di arachidi | C4: cioccolato fondente | G4: caponata
A5: cheerios | C5: crackers riso su riso | G5: carote
A6: cioccolato fondente | C6: fesa di tacchino | G6: cicoria
A7: cornflakes | C7: frutta secca | G7: fagiolini
A8: fette biscottate | C8: pane | G8: finocchi
A9: fiocchi di avena | C9: pane tostato | G9: funghi
A10: kefir | C10: panino | G10: lattuga
A11: latte scramato | C11: parmigiano | G11: melanzane
A12: marmellata | C12: prosciutto cotto | G12: passata di pomodoro
A13: mirtilli | C13: prosciutto crudo | G13: patate
... A30: farina di riso | C30: prugne | G30: alici
C31: uva | G31: calamaro
C32: miele | G32: merluzzo
C33: noci | G33: persico
C34: te | G34: platessa
C35: uova di gallina | G35: polpo
C36: cachi | G36: salmone
G37: salmone affumicato
G38: seppie
G39: tonno
G40: tonno in scatola al naturale
G41: totano
G42: albume
G43: bresaola
G44: fesa di tacchino
G45: fiocchi di latte
G46: fior di latte
G47: philadelphia
G48: primosale
... G83: valeriana

Sheet Foglio10
A1: alimento | B1: grammi | I1: albume | J1: 400
A2: ='menù'!$F3 -> yogurt greco | B2: ='menù'!$G3 -> 150 | I2: anguria | J2: 400
A3: ='menù'!$F4 -> cheerios | B3: ='menù'!$G4 -> 30 | I3: bastoncini | J3: 10
A4: ='menù'!$F5 | B4: ='menù'!$G5 | I4: bevanda di riso | J4: 200
A5: ='menù'!$F6 | B5: ='menù'!$G6 | I5: cioccolato fondente | J5: 80
A6: ='menù'!$F7 -> te | B6: ='menù'!$G7 -> 300 | I6: crackers riso su riso | J6: 90
A7: ='menù'!$F8 -> pane tostato | B7: ='menù'!$G8 -> 40 | I7: fagiolini | J7: 400
A8: ='menù'!$F9 | B8: ='menù'!$G9 | I8: fesa di tacchino | J8: 60
A9: ='menù'!$F10 -> marmellata | B9: ='menù'!$G10 -> 20 | I9: frutta fresca | J9: 150
A10: ='menù'!$F11 -> yogurt greco | B10: ='menù'!$G11 -> 150 | I10: funghi | J10: 400
A11: ='menù'!$F12 -> cheerios | B11: ='menù'!$G12 -> 30 | I11: hamburger di pollo | J11: 200
A12: ='menù'!$F13 | B12: ='menù'!$G13 | I12: hamburger vegetale | J12: 830
A13: ='menù'!$F14 | B13: ='menù'!$G14 | I13: latte scramato | J13: 600
... A46: ='menù'!$F47 | B46: ='menù'!$G47 | I46: broccoli | J46: 200
A47: ='menù'!$F48 -> bevanda di riso | B47: ='menù'!$G48 -> 200
A48: ='menù'!$F49 -> biscotti misura privolat | B48: ='menù'!$G49 -> 30
A49: ='menù'!$F50 | B49: ='menù'!$G50
A50: ='menù'!$F51 | B50: ='menù'!$G51
A51: ='menù'!$F52 -> latte scramato | B51: ='menù'!$G52 -> 200
A52: ='menù'!$F53 -> farina di riso | B52: ='menù'!$G53 -> 50
A53: ='menù'!$F54 -> marmellata | B53: ='menù'!$G54 -> 20
A54: ='menù'!$F55 -> albume | B54: ='menù'!$G55 -> 80
A55: ='menù'!$F56 -> latte scramato | B55: ='menù'!$G56 -> 200
A56: ='menù'!$F57 -> farina di riso | B56: ='menù'!$G57 -> 50
A57: ='menù'!$I3 -> banana | B57: ='menù'!$J3 -> 200
A58: ='menù'!$I4 -> frutta secca | B58: ='menù'!$J4 -> 20
A59: ='menù'!$I5 | B59: ='menù'!$J5
A60: ='menù'!$I6 | B60: ='menù'!$J6
A61: ='menù'!$I7 -> pera | B61: ='menù'!$J7 -> 200
A62: ='menù'!$I8 | B62: ='menù'!$J8
A63: ='menù'!$I9 | B63: ='menù'!$J9
A64: ='menù'!$I10 | B64: ='menù'!$J10
A65: ='menù'!$I11 -> mela | B65: ='menù'!$J11 -> 200
A66: ='menù'!$I12 -> frutta secca | B66: ='menù'!$J12 -> 20
A67: ='menù'!$I13 | B67: ='menù'!$J13
A68: ='menù'!$I14 | B68: ='menù'!$J14
... A110: ='menù'!$I56 -> pera | B110: ='menù'!$J56 -> 200
A111: ='menù'!$I57
A112: ='menù'!$L2 -> pranzo
A113: ='menù'!$L3 -> pane tostato | B113: ='menù'!$M3 -> 100
...

Sheet menù
E1: Menù settimanale
E2: Giovanni | F2: Colazione | I2: spuntino | L2: pranzo | O2: spuntino 2 | R2: cena
E3: lunedi | F3: yogurt greco | G3: 150 | H3: gr | I3: banana | J3: 200 | K3: gr | L3: pane tostato | M3: 100 | N3: gr | O3: pane | P3: 50 | Q3: gr | R3: petto di pollo | S3: 280 | T3: gr
F4: cheerios | G4: 30 | H4: gr | I4: frutta secca | J4: 20 | K4: gr | L4: zucchine | M4: 200 | N4: gr | O4: fesa di tacchino | P4: 120 | Q4: gr | R4: pane tostato | S4: 50 | T4: gr
L5: uova di gallina intero | M5: 120 | N5: gr | R5: minestrone leggerezza | S5: 250 | T5: gr
L6: albume | M6: 100 | N6: gr
E7: martedi | F7: te | G7: 300 | H7: gr | I7: pera | J7: 200 | K7: gr | L7: pasta | M7: 100 | N7: gr | O7: crackers riso su riso | P7: 30 | Q7: gr | R7: arista di maiale | S7: 300 | T7: gr
F8: pane tostato | G8: 40 | H8: gr | L8: primosale | M8: 120 | N8: gr | O8: parmigiano | P8: 40 | Q8: gr | R8: pane tostato | S8: 80 | T8: gr
L9: zucca | M9: 200 | N9: gr | R9: zucca | S9: 200 | T9: gr
F10: marmellata | G10: 20 | H10: gr
E11: mercoledi | F11: yogurt greco | G11: 150 | H11: gr | I11: mela | J11: 200 | K11: gr | L11: zuppa del casale | M11: 300 | N11: gr | O11: pane | P11: 50 | Q11: gr | R11: polpo | S11: 450 | T11: gr
F12: cheerios | G12: 30 | H12: gr | I12: frutta secca | J12: 20 | K12: gr | O12: prosciutto cotto | P12: 100 | Q12: gr | R12: patate | S12: 350 | T12: gr
E15: giovedì | F15: te | G15: 1 | H15: gr | I15: cachi | J15: 200 | K15: gr | L15: pasta | M15: 80 | N15: gr | O15: yogurt greco | P15: 150 | Q15: gr | R15: hamburger vegetale | S15: 200 | T15: gr
F16: pane tostato | G16: 40 | H16: gr | L16: passata di pomodoro | M16: 150 | N16: gr | O16: mela | P16: 200 | Q16: gr | R16: tris di verdure | S16: 200 | T16: gr
F17: marmellata | G17: 20 | H17: gr | L17: fior di latte | M17: 150 | N17: gr | R17: panino | S17: 50
E19: venerdi | F19: yogurt greco | G19: 150 | H19: gr | I19: banana | J19: 200 | K19: gr | L19: pasta | M19: 80 | N19: gr | O19: yogurt greco | P19: 150 | Q19: gr | R19: roastbeef | S19: 300 | T19: gr
F20: cheerios | G20: 30 | H20: gr | L20: pesto | M20: 50 | N20: gr | O20: banana | P20: 200 | Q20: gr | R20: lattuga | S20: 125 | T20: gr
L21: fesa di tacchino | M21: 120 | N21: gr | R21: panino | S21: 80 | T21: gr
E23: sabato | F23: te | G23: 1 | H23: gr | I23: mela | J23: 200 | K23: gr | O23: pane tostato | P23: 60 | Q23: gr | R23: pizza | S23: X | T23: X
F24: pane tostato | G24: 40 | H24: gr | O24: uova di gallina | P24: 120 | Q24: gr
F25: marmellata | G25: 20 | H25: gr
F26: burro di arachidi | G26: 150 | H26: gr
E27: domenica | F27: te | G27: 300 | H27: gr | I27: pera | J27: 200 | K27: gr | L27: pasta | M27: 80 | N27: gr | O27: arance | P27: 200 | Q27: gr | R27: pane tostato | S27: 80 | T27: gr
F28: fette biscottate | G28: 40 | H28: gr | L28: passata di pomodoro | M28: 200 | N28: gr | R28: tris di verdure | S28: 200 | T28: gr
F29: marmellata | G29: 20 | H29: gr | L29: manzo magro macinato | M29: 200 | N29: gr | R29: fesa di tacchino | S29: 100 | T29: gr
R30: philadelphia | S30: 50 | T30: gr
E31: Giovanna | F31: Colazione | I31: spuntino | L31: pranzo | O31: spuntino 2 | R31: cena
E32: lunedi | F32: bevanda di riso | G32: 200 | H32: gr | I32: pera | J32: 25 | K32: gr | L32: uova di gallina intero | M32: 120 | N32: gr | O32: yogurt scremato | P32: 125 | Q32: gr | R32: petto di pollo | S32: 130 | T32: gr
F33: biscotti misura privolat | G33: 30 | H33: gr | L33: zucchine | M33: 200 | N33: gr | O33: frutta secca | P33: 20 | Q33: gr | R33: panko | S33: 30 | T33: gr
R34: minestrone leggerezza | S34: 250 | T34: gr
R35: pane tostato | S35: 20 | T35: gr
E36: martedi | F36: bevanda di riso | G36: 200 | H36: gr | I36: pera | J36: 200 | K36: gr | L36: primosale | M36: 120 | N36: gr | O36: pane tostato | P36: 50 | Q36: gr | R36: pane tostato | S36: 50 | T36: gr
F37: biscotti misura privolat | G37: 30 | H37: gr | L37: zucca | M37: 200 | N37: gr | O37: miele | P37: 10 | Q37: gr | R37: prosciutto cotto | S37: 80 | T37: gr
O38: noci | P38: 10 | Q38: gr | R38: zucca | S38: 200 | T38: gr
E40: mercoledi | F40: bevanda di riso | G40: 200 | H40: gr | I40: cachi | J40: 200 | K40: gr | L40: salmone affumicato | M40: 80 | N40: gr | O40: yogurt greco | P40: 150 | Q40: gr | R40: polpo | S40: 300 | T40: gr
F41: biscotti misura privolat | G41: 30 | H41: gr | L41: valeriana | M41: 50 | N41: gr | O41: miele | P41: 20 | R41: patate | S41: 200 | T41: gr
L42: carote | M42: 150 | N42: gr
E44: giovedì | F44: bevanda di riso | G44: 200 | H44: gr | I44: mela | J44: 200 | K44: gr | L44: fior di latte | M44: 150 | N44: gr | O44: crackers riso su riso | P44: 25 | Q44: gr | R44: hamburger vegetale | S44: 150 | T44: gr
F45: biscotti misura privolat | G45: 30 | H45: gr | L45: melanzane | M45: 200 | N45: gr | R45: tris di verdure | S45: 200 | T45: gr
E48: venerdi | F48: bevanda di riso | G48: 200 | H48: gr | I48: banana | J48: 200 | K48: gr | L48: prosciutto cotto | M48: 80 | N48: gr | O48: yogurt scremato | P48: 125 | Q48: gr | R48: roastbeef | S48: 180 | T48: gr
...
